Workbook

Sheet Read Me
A1: PROMPOLU — Niche analysis & viral content workbook
A2: Prepared 22 Oct 2026 · Sources: prompolu.com, TikTok @prompolu, 479 niche TikTok videos · Instagram posts could not be read
A4: Contents (click a name to jump)
A5: Sheet | B5: What it holds
A6: =HYPERLINK("#'Niche & Strategy'!A1","Niche & Strategy") -> Niche & Strategy | B6: Your niche, audiences, what I could and could not see, the one-paragraph strategy
A7: =HYPERLINK("#'My TikTok Videos'!A1","My TikTok Videos") -> My TikTok Videos | B7: Your 10 visible videos with stats, rates and live medians (filmed vs animated)
A8: =HYPERLINK("#'Niche Patterns'!A1","Niche Patterns") -> Niche Patterns | B8: What goes viral in the niche, with live statistics calculated from the dataset
A9: =HYPERLINK("#'Competitors'!A1","Competitors") -> Competitors | B9: Live account table (calculated from the dataset) plus the full competitor map
A10: =HYPERLINK("#'20 Ideas'!A1","20 Ideas") -> 20 Ideas | B10: The 20 TikTok/Reels ideas: hook, shots, caption, evidence, shoot session
A11: =HYPERLINK("#'Briefs'!A1","Briefs") -> Briefs | B11: Full viral brief for each idea: setup, hooks A/B, sound, caption, pinned comment, sequels, watch-outs
A12: =HYPERLINK("#'Shot Lists'!A1","Shot Lists") -> Shot Lists | B12: Every shot-by-shot table, one row per beat, filterable by idea
A13: =HYPERLINK("#'Strategy Ideas (25)'!A1","Strategy Ideas (25)") -> Strategy Ideas (25) | B13: The 25 ideas from the first strategy report, by pillar
A14: =HYPERLINK("#'Calendar'!A1","Calendar") -> Calendar | B14: Six-week posting calendar with status dropdown, plus shoot sessions
A15: =HYPERLINK("#'30-Day Plan'!A1","30-Day Plan") -> 30-Day Plan | B15: The 30-day plan from the strategy report, with fix-first and measurement lists
A16: =HYPERLINK("#'Results Tracker'!A1","Results Tracker") -> Results Tracker | B16: Fill in your results after 48h; formulas suggest what to do next
A17: =HYPERLINK("#'Rules & Checklists'!A1","Rules & Checklists") -> Rules & Checklists | B17: Rules for every video, production standard, posting checklist, review table
A18: =HYPERLINK("#'Study List'!A1","Study List") -> Study List | B18: Moroccan and international videos worth studying, with links
A19: =HYPERLINK("#'Niche Videos'!A1","Niche Videos") -> Niche Videos | B19: The 479-video dataset with stats and the flags used for the statistics
A20: =HYPERLINK("#'Data Notes'!A1","Data Notes") -> Data Notes | B20: Method, definitions, caveats and what is missing
A22: Colour legend
A23: Blue text | B23: A typed-in number you can change (your video stats, tracker inputs, thresholds).
A24: Black text | B24: A formula, or plain text. Formulas recalculate when the inputs or dataset change.
A25: Yellow fill | B25: A cell for you to fill in (Results Tracker, Calendar status).
A26: Niche Videos sheet | B26: Raw public data read on 22 Oct 2026; the numbers are not changeable inputs, so they are left in black.
A28: Scope of the research | B28: Prepared 22 Oct 2026 from: prompolu.com (all 15 pages), TikTok @prompolu (all 10 visible videos, with stats), and 479 niche videos from TikTok search pages.
A29: Companion files | B29: Companion to tiktok-reels-ideas.md (the 20 ideas) and prompolu-content-strategy.md (the research).
A31: An honest note first
A32: Virality | B32: Nobody can guarantee a video goes viral. TikTok doesn't publish how it ranks videos, and reach is lumpy: in your own account one video in ten passed 10K views, and in the 479-video niche sample the typical video got about 7K while a few got millions. What this playbook does is stack the odds: strong first second, short and clear content, something worth sharing or saving, and a reason to comment. Plan to post often, because the winners are hard to predict.
A33: How to read the briefs | B33: Yours = from your own TikTok results. Niche = from the 479-video sample. Untested = a bet. Darija lines are drafts, so adapt them. Spec numbers (kg, mm, finishes) come from prompolu.com; check them against the STRUGAL sheets before you publish.
A35: Related files in the repository
A36: prompolu-content-strategy.md | B36: Full niche analysis, competitor study, 25 ideas, 30-day plan
A37: tiktok-reels-ideas.md | B37: 20 shoot-ready ideas with hooks and shot lists
A38: viral-video-playbook.md | B38: Detailed viral brief for each of the 20 ideas
A39: data/niche-tiktok-videos.csv | B39: The 479-video dataset (third-party phone numbers redacted)

Sheet Niche & Strategy
A1: Niche, audiences and strategy
A2: Text from the strategy report, sections 0, 1 and 5
A4: What I could and could not see
A5: Source | B5: What I got | C5: Gap
A6: prompolu.com | B6: Full read of every page in the sitemap | C6: —
A7: TikTok @prompolu | B7: Profile stats; 10 of 12 videos with exact views, likes, shares, saves, caption, date, cover and frames from the top 3 | C7: 2 videos weren't listed publicly
A8: Instagram @prompolu | B8: Only the headline numbers: 151 followers, 7 following, 15 posts | C8: Instagram blocks logged-out visitors, so I could not see a single post, caption or view count. Nothing below about your Instagram content is data-based.
A9: Competitors | B9: 479 public TikTok videos (188 Moroccan) with exact stats | C9: No Instagram competitor data at all. The sample is what TikTok surfaces for niche searches, so it leans toward popular videos.
B11: If you export Instagram Insights (or screenshot your top 5 reels), I can run the same analysis there.
A13: Your niche
B14: B2B aluminium profile supply for window, door and kitchen fabricators, with an AR sales tool that gives your customers a way to sell.
B15: • You are the official STRUGAL distributor for Fès, Sefrou and the surrounding region (stores on Av. El Wafaa in Fès and Route d'El Menzel in Sefrou), 18+ years in business, delivery across Morocco.
B16: • You sell raw material, not finished windows: 11 sliding systems (S70P to S140RP Infinity), casement systems (S53RP+, S46) plus ALUDOORS doors, interior fit-out profiles (kitchens and dressings with integrated handles), and exterior lines (railings, roller shutters, pergolas, cladding).
B17: • Your customers are menuisiers. Their customers are homeowners who say "I can't picture it".
B18: • Your unfair advantage is the 3D/AR tool (pergola, railing, sliding bay, casement). It's white-labelled to each menuisier, needs no app, loads in about a second on 4G, and returns a complete WhatsApp quote request. I found no competitor in my sample showing anything like it.
B19: • Your voice on the site is plain, practical and workshop-friendly: "Quatre étapes, sans formalité inutile."
B20: Two audiences, one funnel.
B21: 1. Menuisiers (buyers). They care about stock, colours, specs, hardware tricks, delivery and not wasting time.
B22: 2. Homeowners (demand creators). If they ask their menuisier for STRUGAL, the menuisier comes to you. Most of the views in this niche come from this group.
B23: Your content should serve the first group and use the second as a pull-through. Views from homeowners who can't buy from you are nice but they don't pay the bills. Measure WhatsApp enquiries, not views.
A25: Strategy in one paragraph
B26: Own the "workshop's best friend" lane in Darija and French. Post real stock and real hands, with a person who knows the product, at a steady rhythm. Use the viral "one clever mechanism" format on your own STRUGAL systems. Use the 3D/AR tool as your signature series. Pull homeowners toward asking for STRUGAL by name. Put the hook in the first second as on-screen text, caption in Arabic or short French with 3–5 tags, and keep the phone number on the video.

Sheet My TikTok Videos
A1: Your TikTok videos (@prompolu)
A2: 10 of 12 videos were visible. Stats read from the public video pages on 22 Oct 2026. Blue = typed-in data; black = formula.
A4: Video ID | B4: Posted | C4: Type | D4: What it is | E4: Views | F4: Likes | G4: Comments | H4: Shares | I4: Saves | J4: Length (s) | K4: Like rate | L4: Share rate | M4: Save rate | N4: Caption as posted | O4: Music | P4: Notes from the report
A5: 7636091127908650247 | B5: 46146 | C5: Filmed | D5: Folding mosquito net in 3 colours (showroom) | E5: 2732 | F5: 38 | G5: 2 | H5: 25 | I5: 7 | J5: 41 | K5: =IFERROR(F5/E5,0) -> 0.013909224 | L5: =IFERROR(H5/E5,0) -> 0.0091508053 | M5: =IFERROR(I5/E5,0) -> 0.0025622255 | N5: moustiquaire plissé disponible en gris givré , blanc et quartz . #fesal #fes #maroc #moustiquaire #fenetre | O5: Original sound | P5: 25 shares on 2.7K views, a high share count for its reach.
A6: 7657562891347954952 | B6: 46204 | C6: Filmed | D6: Kitchen accessories in the showroom | E6: 2135 | F6: 44 | G6: 4 | H6: 11 | I6: 11 | J6: 84 | K6: =IFERROR(F6/E6,0) -> 0.020608899 | L6: =IFERROR(H6/E6,0) -> 0.0051522248 | M6: =IFERROR(I6/E6,0) -> 0.0051522248 | N6: Accessoires de cuisine #accessoires #aluminum #fes #construction | O6: Original sound
A7: 7671325847072034056 | B7: 46241 | C7: Filmed | D7: POV walk through the stock aisles, colour list on screen | E7: 8073 | F7: 79 | G7: 5 | H7: 14 | I7: 10 | J7: 22 | K7: =IFERROR(F7/E7,0) -> 0.0097857054 | L7: =IFERROR(H7/E7,0) -> 0.0017341756 | M7: =IFERROR(I7/E7,0) -> 0.0012386969 | N7: #fesal #aluminium #fyp #fenêtre #maroc | O7: Original sound | P7: 79 likes, 14 shares.
A8: 7672143043700477202 | B8: 46243 | C8: Filmed | D8: Truck piled with profile bars in a Fès street | E8: 14700 | F8: 127 | G8: 3 | H8: 20 | I8: 15 | J8: 16 | K8: =IFERROR(F8/E8,0) -> 0.0086394558 | L8: =IFERROR(H8/E8,0) -> 0.0013605442 | M8: =IFERROR(I8/E8,0) -> 0.0010204082 | N8: #fyp #fesal #aluminium #maroc #fes | O8: Original sound | P8: 127 likes, 20 shares. No talking, phone number on screen. Your best video.
A9: 7681711882801122578 | B9: 46269 | C9: Filmed | D9: Presenter at the counter: dust fix for the flat lock (verrou plat) | E9: 4546 | F9: 131 | G9: 11 | H9: 26 | I9: 23 | J9: 29 | K9: =IFERROR(F9/E9,0) -> 0.028816542 | L9: =IFERROR(H9/E9,0) -> 0.0057193137 | M9: =IFERROR(I9/E9,0) -> 0.0050593929 | N9: Solution contre poussière pour le verou plat .#fes #alumminium #fenetre #maroc #morocco | O9: Original sound | P9: Most saves (23), shares (26) and comments (11) of any of your videos. 131 likes.
A10: 7689881301532364040 | B10: 46291 | C10: Animated | D10: Profile render, 'Précision architecturale' | E10: 653 | F10: 21 | G10: 2 | H10: 11 | I10: 0 | J10: 8 | K10: =IFERROR(F10/E10,0) -> 0.032159265 | L10: =IFERROR(H10/E10,0) -> 0.016845329 | M10: =IFERROR(I10/E10,0) -> 0 | N10: Decouvrir les autres gammes dans notre siteweb en bio #strugal #aluminium #fes #viral | O10: Licensed: the world we knew (luxury) | P10: Licensed music.
A11: 7689923806797876498 | B11: 46291 | C11: Animated | D11: 'Hello!' brand animation | E11: 227 | F11: 8 | G11: 2 | H11: 0 | I11: 1 | J11: 15 | K11: =IFERROR(F11/E11,0) -> 0.035242291 | L11: =IFERROR(H11/E11,0) -> 0 | M11: =IFERROR(I11/E11,0) -> 0.0044052863 | N11: Retrouvez-nous sur notre site web #aluminium #fes #immobilier #strugal #prompolu | O11: Original sound
A12: 7690695193615617287 | B12: 46293 | C12: Animated | D12: P-logo animation | E12: 312 | F12: 12 | G12: 2 | H12: 9 | I12: 1 | J12: 17 | K12: =IFERROR(F12/E12,0) -> 0.038461538 | L12: =IFERROR(H12/E12,0) -> 0.028846154 | M12: =IFERROR(I12/E12,0) -> 0.0032051282 | N12: Retrouvez nous sur notre siteweb prompolu.com #strugal #aluminium #fes #maroc #ai | O12: Original sound | P12: Caption mentions #ai.
A13: 7698422583078751506 | B13: 46314 | C13: Animated | D13: Brand motion piece | E13: 324 | F13: 14 | G13: 1 | H13: 5 | I13: 0 | J13: 15 | K13: =IFERROR(F13/E13,0) -> 0.043209877 | L13: =IFERROR(H13/E13,0) -> 0.015432099 | M13: =IFERROR(I13/E13,0) -> 0 | N13: Les gammes STRUGAL sont disponibles, Laissez nous vous aidez à trouver le profil qui répond à vos besoins. retrouvez nous sur prompolu.com . #strugal #architecture #viral #aluminium #maroc | O13: Licensed: Velvet Poolside | P13: Licensed music. Only 3 days old.
A14: 7699069673593228562 | B14: 46316 | C14: Animated | D14: Brand motion piece, LANDSCAPE 1024×576 (only 1–3 days old) | E14: 147 | F14: 13 | G14: 1 | H14: 10 | I14: 1 | J14: 20 | K14: =IFERROR(F14/E14,0) -> 0.088435374 | L14: =IFERROR(H14/E14,0) -> 0.068027211 | M14: =IFERROR(I14/E14,0) -> 0.0068027211 | N14: Nouveau style, nouvelle perspective. Retrouvez nous sur notre siteweb www.prompolu.com #strugal #architecture #aluminium #maison #fes . | O14: Original sound | P14: Landscape 16:9. Only 1 day old.
A16: Summary (formulas)
A17: Total views | E17: =SUM(E5:E14) -> 33849
A18: Median views, all 10 | E18: =MEDIAN(E5:E14) -> 1394
A19: Average views, all 10 | E19: =AVERAGE(E5:E14) -> 3384.9
A20: Median views, 5 filmed (rows 5–9) | E20: =MEDIAN(E5:E9) -> 4546
A21: Median views, 5 animated (rows 10–14) | E21: =MEDIAN(E10:E14) -> 312
A22: Filmed ÷ animated (×) | E22: =IFERROR(E20/E21,0) -> 14.570513
A23: Videos above 10,000 views | E23: =COUNTIF(E5:E14,">10000") -> 1
A25: Profile snapshot (typed-in)
A26: Platform | B26: Followers | C26: Following | D26: Likes / posts
A27: TikTok @prompolu | B27: 386 | C27: 4 | D27: 739 likes · 12 videos
A28: Instagram @prompolu | B28: 151 | C28: 7 | D28: 15 posts (posts not readable)
A30: What stands out
D31: 1. Real footage beats brand graphics by about 14×. The five filmed videos have a median of 4,546 views. The five animated or brand-graphic videos have a median of 312. The last two are only 1–3 days old, but the three from 26–28 Sep have had 3+ weeks and are flat. Your audience came for the stock, the trucks and the person at the counter.
D32: 2. Your tip video is the quality signal. It has a third of the truck's views but more saves, shares and comments in absolute numbers. People save and send it. (Rates per view are misleading on your small videos, because their few viewers are mostly followers.) It's the format to build a series on.
D33: 3. Your two biggest videos have hashtag-only captions (#fyp #fesal #aluminium #maroc #fes and similar). The next three add a one-line description. The weak ones say "Retrouvez-nous sur notre site" with #strugal. (#strugal is on all 5 of your weakest videos and none of your top 5. The animated videos also share that tag, so treat it as a hint, not proof.)
D34: 4. The Oct 21 video is landscape (1024×576). On a phone it plays as a thin letterboxed strip. Re-export everything as 9:16.
D35: 5. Posting is sporadic: 10 videos in 5.5 months, with an 8-week gap in May–July. TikTok can't learn who to show you to at this pace.
D36: 6. Brand mismatch. Your top videos carry a "Fesal.aluminium" watermark, the site's footer links to instagram.com/fesal.aluminium and tiktok.com/@fesal.aluminium, but your accounts are @prompolu. TikTok returned an error for @fesal.aluminium and Instagram showed only a login wall for it, so I couldn't confirm either account exists. Check these links; if they're dead or someone else's, you're sending visitors to the wrong place.

Sheet Niche Patterns
A1: What goes viral in the niche
A2: Statistics below are live formulas over the 'Niche Videos' sheet. Medians use array formulas.
A4: Sample size
A5: Videos in the sample | B5: =COUNT('Niche Videos'!$F$2:$F$480) -> 479
A6: Moroccan-tagged videos | B6: =COUNTIF('Niche Videos'!$K$2:$K$480,"yes") -> 188
A7: Median views, all videos | B7: =MEDIAN('Niche Videos'!$F$2:$F$480) -> 7052
A8: Median views, Moroccan videos | B8: {=MEDIAN(IF('Niche Videos'!$K$2:$K$480="yes",'Niche Videos'!$F$2:$F$480))} -> 8810
A9: Median share rate (shares ÷ views), all | B9: =MEDIAN('Niche Videos'!$M$2:$M$480) -> 0.0022857143
A10: Median save rate (saves ÷ views), all | B10: =MEDIAN('Niche Videos'!$N$2:$N$480) -> 0.0028632785
A12: Caption effects (Moroccan videos only)
A13: Caption feature | B13: n with | C13: Median views, with | D13: n without | E13: Median views, without | F13: With ÷ without (×) | G13: Reading
A14: Arabic caption | B14: =COUNTIFS('Niche Videos'!$K$2:$K$480,"yes",'Niche Videos'!$O$2:$O$480,1) -> 85 | C14: {=IFERROR(MEDIAN(IF(('Niche Videos'!$K$2:$K$480="yes")*('Niche Videos'!$O$2:$O$480=1),'Niche Videos'!$F$2:$F$480)),"n/a")} -> 18200 | D14: =COUNTIFS('Niche Videos'!$K$2:$K$480,"yes",'Niche Videos'!$O$2:$O$480,0) -> 103 | E14: {=IFERROR(MEDIAN(IF(('Niche Videos'!$K$2:$K$480="yes")*('Niche Videos'!$O$2:$O$480=0),'Niche Videos'!$F$2:$F$480)),"n/a")} -> 4539 | F14: =IFERROR(C14/E14,"n/a") -> 4.0096938 | G14: About 4× the reach with Arabic (correlation, not proof)
A15: Hashtag-only caption (no text) | B15: =COUNTIFS('Niche Videos'!$K$2:$K$480,"yes",'Niche Videos'!$P$2:$P$480,1) -> 45 | C15: {=IFERROR(MEDIAN(IF(('Niche Videos'!$K$2:$K$480="yes")*('Niche Videos'!$P$2:$P$480=1),'Niche Videos'!$F$2:$F$480)),"n/a")} -> 16800 | D15: =COUNTIFS('Niche Videos'!$K$2:$K$480,"yes",'Niche Videos'!$P$2:$P$480,0) -> 143 | E15: {=IFERROR(MEDIAN(IF(('Niche Videos'!$K$2:$K$480="yes")*('Niche Videos'!$P$2:$P$480=0),'Niche Videos'!$F$2:$F$480)),"n/a")} -> 6833 | F15: =IFERROR(C15/E15,"n/a") -> 2.4586565 | G15: Short captions did better
A16: Phone number in the caption | B16: =COUNTIFS('Niche Videos'!$K$2:$K$480,"yes",'Niche Videos'!$Q$2:$Q$480,1) -> 53 | C16: {=IFERROR(MEDIAN(IF(('Niche Videos'!$K$2:$K$480="yes")*('Niche Videos'!$Q$2:$Q$480=1),'Niche Videos'!$F$2:$F$480)),"n/a")} -> 4768 | D16: =COUNTIFS('Niche Videos'!$K$2:$K$480,"yes",'Niche Videos'!$Q$2:$Q$480,0) -> 135 | E16: {=IFERROR(MEDIAN(IF(('Niche Videos'!$K$2:$K$480="yes")*('Niche Videos'!$Q$2:$Q$480=0),'Niche Videos'!$F$2:$F$480)),"n/a")} -> 13900 | F16: =IFERROR(C16/E16,"n/a") -> 0.34302158 | G16: Numbers in the caption did worse; put it on the video instead
A18: Topic effects (all videos whose caption mentions the topic; categories overlap)
A19: Topic | B19: n videos | C19: Median views | D19: Median share rate | E19: Median save rate | G19: Reading
A20: Kitchen / cuisine | B20: =COUNTIF('Niche Videos'!$R$2:$R$480,1) -> 80 | C20: {=IFERROR(MEDIAN(IF('Niche Videos'!$R$2:$R$480=1,'Niche Videos'!$F$2:$F$480)),"n/a")} -> 29950 | D20: {=IFERROR(MEDIAN(IF('Niche Videos'!$R$2:$R$480=1,'Niche Videos'!$M$2:$M$480)),"n/a")} -> 0.0039059666 | E20: {=IFERROR(MEDIAN(IF('Niche Videos'!$R$2:$R$480=1,'Niche Videos'!$N$2:$N$480)),"n/a")} -> 0.0032004814 | G20: Biggest category in Moroccan aluminium TikTok
A21: Mosquito net | B21: =COUNTIF('Niche Videos'!$S$2:$S$480,1) -> 6 | C21: {=IFERROR(MEDIAN(IF('Niche Videos'!$S$2:$S$480=1,'Niche Videos'!$F$2:$F$480)),"n/a")} -> 5974 | D21: {=IFERROR(MEDIAN(IF('Niche Videos'!$S$2:$S$480=1,'Niche Videos'!$M$2:$M$480)),"n/a")} -> 0.0045718405 | E21: {=IFERROR(MEDIAN(IF('Niche Videos'!$S$2:$S$480=1,'Niche Videos'!$N$2:$N$480)),"n/a")} -> 0.0040105352 | G21: Small sample; high share rate
A22: Sliding / coulissant | B22: =COUNTIF('Niche Videos'!$T$2:$T$480,1) -> 126 | C22: {=IFERROR(MEDIAN(IF('Niche Videos'!$T$2:$T$480=1,'Niche Videos'!$F$2:$F$480)),"n/a")} -> 10244 | D22: {=IFERROR(MEDIAN(IF('Niche Videos'!$T$2:$T$480=1,'Niche Videos'!$M$2:$M$480)),"n/a")} -> 0.0030095558 | E22: {=IFERROR(MEDIAN(IF('Niche Videos'!$T$2:$T$480=1,'Niche Videos'!$N$2:$N$480)),"n/a")} -> 0.0034306226
A23: Pergola / terrace | B23: =COUNTIF('Niche Videos'!$U$2:$U$480,1) -> 38 | C23: {=IFERROR(MEDIAN(IF('Niche Videos'!$U$2:$U$480=1,'Niche Videos'!$F$2:$F$480)),"n/a")} -> 2480.5 | D23: {=IFERROR(MEDIAN(IF('Niche Videos'!$U$2:$U$480=1,'Niche Videos'!$M$2:$M$480)),"n/a")} -> 0.0018542433 | E23: {=IFERROR(MEDIAN(IF('Niche Videos'!$U$2:$U$480=1,'Niche Videos'!$N$2:$N$480)),"n/a")} -> 0.002052779
A24: Railing / garde-corps | B24: =COUNTIF('Niche Videos'!$V$2:$V$480,1) -> 61 | C24: {=IFERROR(MEDIAN(IF('Niche Videos'!$V$2:$V$480=1,'Niche Videos'!$F$2:$F$480)),"n/a")} -> 2462 | D24: {=IFERROR(MEDIAN(IF('Niche Videos'!$V$2:$V$480=1,'Niche Videos'!$M$2:$M$480)),"n/a")} -> 0.002615193 | E24: {=IFERROR(MEDIAN(IF('Niche Videos'!$V$2:$V$480=1,'Niche Videos'!$N$2:$N$480)),"n/a")} -> 0.002983871
A25: Window / fenêtre | B25: =COUNTIF('Niche Videos'!$W$2:$W$480,1) -> 98 | C25: {=IFERROR(MEDIAN(IF('Niche Videos'!$W$2:$W$480=1,'Niche Videos'!$F$2:$F$480)),"n/a")} -> 2013 | D25: {=IFERROR(MEDIAN(IF('Niche Videos'!$W$2:$W$480=1,'Niche Videos'!$M$2:$M$480)),"n/a")} -> 0.0011998391 | E25: {=IFERROR(MEDIAN(IF('Niche Videos'!$W$2:$W$480=1,'Niche Videos'!$N$2:$N$480)),"n/a")} -> 0.0018068146 | G25: Windows alone are weak reach
A26: Door / porte | B26: =COUNTIF('Niche Videos'!$X$2:$X$480,1) -> 147 | C26: {=IFERROR(MEDIAN(IF('Niche Videos'!$X$2:$X$480=1,'Niche Videos'!$F$2:$F$480)),"n/a")} -> 14100 | D26: {=IFERROR(MEDIAN(IF('Niche Videos'!$X$2:$X$480=1,'Niche Videos'!$M$2:$M$480)),"n/a")} -> 0.0024376731 | E26: {=IFERROR(MEDIAN(IF('Niche Videos'!$X$2:$X$480=1,'Niche Videos'!$N$2:$N$480)),"n/a")} -> 0.0032137118
A27: Dressing / wardrobe | B27: =COUNTIF('Niche Videos'!$Y$2:$Y$480,1) -> 20 | C27: {=IFERROR(MEDIAN(IF('Niche Videos'!$Y$2:$Y$480=1,'Niche Videos'!$F$2:$F$480)),"n/a")} -> 7960 | D27: {=IFERROR(MEDIAN(IF('Niche Videos'!$Y$2:$Y$480=1,'Niche Videos'!$M$2:$M$480)),"n/a")} -> 0.0031978322 | E27: {=IFERROR(MEDIAN(IF('Niche Videos'!$Y$2:$Y$480=1,'Niche Videos'!$N$2:$N$480)),"n/a")} -> 0.0023680904
A28: Shower | B28: =COUNTIF('Niche Videos'!$Z$2:$Z$480,1) -> 9 | C28: {=IFERROR(MEDIAN(IF('Niche Videos'!$Z$2:$Z$480=1,'Niche Videos'!$F$2:$F$480)),"n/a")} -> 4692 | D28: {=IFERROR(MEDIAN(IF('Niche Videos'!$Z$2:$Z$480=1,'Niche Videos'!$M$2:$M$480)),"n/a")} -> 0.00088731145 | E28: {=IFERROR(MEDIAN(IF('Niche Videos'!$Z$2:$Z$480=1,'Niche Videos'!$N$2:$N$480)),"n/a")} -> 0.00099307159
A29: Accessories / hardware | B29: =COUNTIF('Niche Videos'!$AA$2:$AA$480,1) -> 9 | C29: {=IFERROR(MEDIAN(IF('Niche Videos'!$AA$2:$AA$480=1,'Niche Videos'!$F$2:$F$480)),"n/a")} -> 8317 | D29: {=IFERROR(MEDIAN(IF('Niche Videos'!$AA$2:$AA$480=1,'Niche Videos'!$M$2:$M$480)),"n/a")} -> 0.001363174 | E29: {=IFERROR(MEDIAN(IF('Niche Videos'!$AA$2:$AA$480=1,'Niche Videos'!$N$2:$N$480)),"n/a")} -> 0.0031261272
A30: Facade / vitrine | B30: =COUNTIF('Niche Videos'!$AB$2:$AB$480,1) -> 29 | C30: {=IFERROR(MEDIAN(IF('Niche Videos'!$AB$2:$AB$480=1,'Niche Videos'!$F$2:$F$480)),"n/a")} -> 4436 | D30: {=IFERROR(MEDIAN(IF('Niche Videos'!$AB$2:$AB$480=1,'Niche Videos'!$M$2:$M$480)),"n/a")} -> 0.0024888004 | E30: {=IFERROR(MEDIAN(IF('Niche Videos'!$AB$2:$AB$480=1,'Niche Videos'!$N$2:$N$480)),"n/a")} -> 0.0029906542
A31: Before / after | B31: =COUNTIF('Niche Videos'!$AC$2:$AC$480,1) -> 15 | C31: {=IFERROR(MEDIAN(IF('Niche Videos'!$AC$2:$AC$480=1,'Niche Videos'!$F$2:$F$480)),"n/a")} -> 1476 | D31: {=IFERROR(MEDIAN(IF('Niche Videos'!$AC$2:$AC$480=1,'Niche Videos'!$M$2:$M$480)),"n/a")} -> 0.001845586 | E31: {=IFERROR(MEDIAN(IF('Niche Videos'!$AC$2:$AC$480=1,'Niche Videos'!$N$2:$N$480)),"n/a")} -> 0.0026071429
A32: Price / prix / devis | B32: =COUNTIF('Niche Videos'!$AD$2:$AD$480,1) -> 30 | C32: {=IFERROR(MEDIAN(IF('Niche Videos'!$AD$2:$AD$480=1,'Niche Videos'!$F$2:$F$480)),"n/a")} -> 12250 | D32: {=IFERROR(MEDIAN(IF('Niche Videos'!$AD$2:$AD$480=1,'Niche Videos'!$M$2:$M$480)),"n/a")} -> 0.0023559633 | E32: {=IFERROR(MEDIAN(IF('Niche Videos'!$AD$2:$AD$480=1,'Niche Videos'!$N$2:$N$480)),"n/a")} -> 0.0038292861 | G32: High save rate: price content gets kept
A34: Length buckets (bounds in blue are editable)
A35: Bucket (seconds) | B35: From (≥) | C35: To (<) | D35: n, all | E35: Median views, all | F35: n, Moroccan | G35: Median views, Moroccan
A36: 0–10 | B36: 0 | C36: 10 | D36: =COUNTIFS('Niche Videos'!$E$2:$E$480,">="&B36,'Niche Videos'!$E$2:$E$480,"<"&C36) -> 35 | E36: {=IFERROR(MEDIAN(IF(('Niche Videos'!$E$2:$E$480>=B36)*('Niche Videos'!$E$2:$E$480<C36),'Niche Videos'!$F$2:$F$480)),"n/a")} -> 10500 | F36: =COUNTIFS('Niche Videos'!$E$2:$E$480,">="&B36,'Niche Videos'!$E$2:$E$480,"<"&C36,'Niche Videos'!$K$2:$K$480,"yes") -> 4 | G36: {=IFERROR(MEDIAN(IF(('Niche Videos'!$E$2:$E$480>=B36)*('Niche Videos'!$E$2:$E$480<C36)*('Niche Videos'!$K$2:$K$480="yes"),'Niche Videos'!$F$2:$F$480)),"n/a")} -> 914000
A37: 10–20 | B37: 10 | C37: 20 | D37: =COUNTIFS('Niche Videos'!$E$2:$E$480,">="&B37,'Niche Videos'!$E$2:$E$480,"<"&C37) -> 105 | E37: {=IFERROR(MEDIAN(IF(('Niche Videos'!$E$2:$E$480>=B37)*('Niche Videos'!$E$2:$E$480<C37),'Niche Videos'!$F$2:$F$480)),"n/a")} -> 7979 | F37: =COUNTIFS('Niche Videos'!$E$2:$E$480,">="&B37,'Niche Videos'!$E$2:$E$480,"<"&C37,'Niche Videos'!$K$2:$K$480,"yes") -> 33 | G37: {=IFERROR(MEDIAN(IF(('Niche Videos'!$E$2:$E$480>=B37)*('Niche Videos'!$E$2:$E$480<C37)*('Niche Videos'!$K$2:$K$480="yes"),'Niche Videos'!$F$2:$F$480)),"n/a")} -> 7468
A38: 20–35 | B38: 20 | C38: 35 | D38: =COUNTIFS('Niche Videos'!$E$2:$E$480,">="&B38,'Niche Videos'!$E$2:$E$480,"<"&C38) -> 144 | E38: {=IFERROR(MEDIAN(IF(('Niche Videos'!$E$2:$E$480>=B38)*('Niche Videos'!$E$2:$E$480<C38),'Niche Videos'!$F$2:$F$480)),"n/a")} -> 3855.5 | F38: =COUNTIFS('Niche Videos'!$E$2:$E$480,">="&B38,'Niche Videos'!$E$2:$E$480,"<"&C38,'Niche Videos'!$K$2:$K$480,"yes") -> 62 | G38: {=IFERROR(MEDIAN(IF(('Niche Videos'!$E$2:$E$480>=B38)*('Niche Videos'!$E$2:$E$480<C38)*('Niche Videos'!$K$2:$K$480="yes"),'Niche Videos'!$F$2:$F$480)),"n/a")} -> 4487.5
A39: 35–60 | B39: 35 | C39: 60 | D39: =COUNTIFS('Niche Videos'!$E$2:$E$480,">="&B39,'Niche Videos'!$E$2:$E$480,"<"&C39) -> 104 | E39: {=IFERROR(MEDIAN(IF(('Niche Videos'!$E$2:$E$480>=B39)*('Niche Videos'!$E$2:$E$480<C39),'Niche Videos'!$F$2:$F$480)),"n/a")} -> 6955.5 | F39: =COUNTIFS('Niche Videos'!$E$2:$E$480,">="&B39,'Niche Videos'!$E$2:$E$480,"<"&C39,'Niche Videos'!$K$2:$K$480,"yes") -> 50 | G39: {=IFERROR(MEDIAN(IF(('Niche Videos'!$E$2:$E$480>=B39)*('Niche Videos'!$E$2:$E$480<C39)*('Niche Videos'!$K$2:$K$480="yes"),'Niche Videos'!$F$2:$F$480)),"n/a")} -> 7294
A40: 60 and over | B40: 60 | C40: 100000 | D40: =COUNTIFS('Niche Videos'!$E$2:$E$480,">="&B40,'Niche Videos'!$E$2:$E$480,"<"&C40) -> 91 | E40: {=IFERROR(MEDIAN(IF(('Niche Videos'!$E$2:$E$480>=B40)*('Niche Videos'!$E$2:$E$480<C40),'Niche Videos'!$F$2:$F$480)),"n/a")} -> 11000 | F40: =COUNTIFS('Niche Videos'!$E$2:$E$480,">="&B40,'Niche Videos'!$E$2:$E$480,"<"&C40,'Niche Videos'!$K$2:$K$480,"yes") -> 39 | G40: {=IFERROR(MEDIAN(IF(('Niche Videos'!$E$2:$E$480>=B40)*('Niche Videos'!$E$2:$E$480<C40)*('Niche Videos'!$K$2:$K$480="yes"),'Niche Videos'!$F$2:$F$480)),"n/a")} -> 15600
A41: Length is a weak signal: under 10 s and over 60 s did better than 20–35 s, but the Moroccan under-10 s group has only a few videos. Hook strength matters more than length.
A43: The big winners (typed from the report)
A44: Who | B44: Views | G44: What
A45: @chinawindowsdoors (206K followers) | B45: 9.0M | G45: 18s: "Easy to install, waterproof, and able to block space" (a folding/sliding door demo)
...

Sheet Competitors
A1: Competitor map
A2: Top table: live formulas over the 'Niche Videos' sheet (videos seen in the sample only). Below: the full competitor text from the report.
A4: Account | B4: Followers | C4: Segment | D4: Videos seen | E4: Median views | F4: Best video (views) | G4: Note
A5: @proalumad | B5: =IFERROR(INDEX('Niche Videos'!$C$2:$C$480,MATCH("proalumad",'Niche Videos'!$B$2:$B$480,0)),"n/a") -> 602200 | C5: Tier 1: kitchen fabricator | D5: =COUNTIF('Niche Videos'!$B$2:$B$480,"proalumad") -> 7 | E5: {=IFERROR(MEDIAN(IF('Niche Videos'!$B$2:$B$480="proalumad",'Niche Videos'!$F$2:$F$480)),"n/a")} -> 1300000 | F5: {=IFERROR(MAX(IF('Niche Videos'!$B$2:$B$480="proalumad",'Niche Videos'!$F$2:$F$480)),"n/a")} -> 8300000 | G5: Short silent reveals, Arabic hashtags, no spoken caption. A template for the format.
A6: @alu.mamoune | B6: =IFERROR(INDEX('Niche Videos'!$C$2:$C$480,MATCH("alu.mamoune",'Niche Videos'!$B$2:$B$480,0)),"n/a") -> 18100 | C6: Tier 1: kitchens | D6: =COUNTIF('Niche Videos'!$B$2:$B$480,"alu.mamoune") -> 4 | E6: {=IFERROR(MEDIAN(IF('Niche Videos'!$B$2:$B$480="alu.mamoune",'Niche Videos'!$F$2:$F$480)),"n/a")} -> 182200 | F6: {=IFERROR(MAX(IF('Niche Videos'!$B$2:$B$480="alu.mamoune",'Niche Videos'!$F$2:$F$480)),"n/a")} -> 1700000 | G6: 51-second kitchen reached 1.7M with 18K followers.
A7: @alocuisines | B7: =IFERROR(INDEX('Niche Videos'!$C$2:$C$480,MATCH("alocuisines",'Niche Videos'!$B$2:$B$480,0)),"n/a") -> 47400 | C7: Tier 1: kitchens | D7: =COUNTIF('Niche Videos'!$B$2:$B$480,"alocuisines") -> 5 | E7: {=IFERROR(MEDIAN(IF('Niche Videos'!$B$2:$B$480="alocuisines",'Niche Videos'!$F$2:$F$480)),"n/a")} -> 45700 | F7: {=IFERROR(MAX(IF('Niche Videos'!$B$2:$B$480="alocuisines",'Niche Videos'!$F$2:$F$480)),"n/a")} -> 446300
A8: @aluminium_oujaiou | B8: =IFERROR(INDEX('Niche Videos'!$C$2:$C$480,MATCH("aluminium_oujaiou",'Niche Videos'!$B$2:$B$480,0)),"n/a") -> 23700 | C8: Tier 1: kitchens and interior doors | D8: =COUNTIF('Niche Videos'!$B$2:$B$480,"aluminium_oujaiou") -> 3 | E8: {=IFERROR(MEDIAN(IF('Niche Videos'!$B$2:$B$480="aluminium_oujaiou",'Niche Videos'!$F$2:$F$480)),"n/a")} -> 140600 | F8: {=IFERROR(MAX(IF('Niche Videos'!$B$2:$B$480="aluminium_oujaiou",'Niche Videos'!$F$2:$F$480)),"n/a")} -> 204000
A9: @zaki.aluminiumpro | B9: =IFERROR(INDEX('Niche Videos'!$C$2:$C$480,MATCH("zaki.aluminiumpro",'Niche Videos'!$B$2:$B$480,0)),"n/a") -> 12900 | C9: Tier 1: Casablanca menuiserie | D9: =COUNTIF('Niche Videos'!$B$2:$B$480,"zaki.aluminiumpro") -> 14 | E9: {=IFERROR(MEDIAN(IF('Niche Videos'!$B$2:$B$480="zaki.aluminiumpro",'Niche Videos'!$F$2:$F$480)),"n/a")} -> 18450 | F9: {=IFERROR(MAX(IF('Niche Videos'!$B$2:$B$480="zaki.aluminiumpro",'Niche Videos'!$F$2:$F$480)),"n/a")} -> 161600
A10: @aluminooo | B10: =IFERROR(INDEX('Niche Videos'!$C$2:$C$480,MATCH("aluminooo",'Niche Videos'!$B$2:$B$480,0)),"n/a") -> 74500 | C10: Tier 1: shower cabins | D10: =COUNTIF('Niche Videos'!$B$2:$B$480,"aluminooo") -> 8 | E10: {=IFERROR(MEDIAN(IF('Niche Videos'!$B$2:$B$480="aluminooo",'Niche Videos'!$F$2:$F$480)),"n/a")} -> 5293 | F10: {=IFERROR(MAX(IF('Niche Videos'!$B$2:$B$480="aluminooo",'Niche Videos'!$F$2:$F$480)),"n/a")} -> 839000 | G10: WhatsApp number in the caption; best video 839K.
A11: @rm_accessoires1 | B11: =IFERROR(INDEX('Niche Videos'!$C$2:$C$480,MATCH("rm_accessoires1",'Niche Videos'!$B$2:$B$480,0)),"n/a") -> 2282 | C11: Tier 2: wholesale hardware | D11: =COUNTIF('Niche Videos'!$B$2:$B$480,"rm_accessoires1") -> 1 | E11: {=IFERROR(MEDIAN(IF('Niche Videos'!$B$2:$B$480="rm_accessoires1",'Niche Videos'!$F$2:$F$480)),"n/a")} -> 8317 | F11: {=IFERROR(MAX(IF('Niche Videos'!$B$2:$B$480="rm_accessoires1",'Niche Videos'!$F$2:$F$480)),"n/a")} -> 8317 | G11: Charnière 3D wholesale clip: 8.3K views for a tiny account.
A12: @skymaxmaroc.ma | B12: =IFERROR(INDEX('Niche Videos'!$C$2:$C$480,MATCH("skymaxmaroc.ma",'Niche Videos'!$B$2:$B$480,0)),"n/a") -> 3247 | C12: Tier 2: cladding supplier | D12: =COUNTIF('Niche Videos'!$B$2:$B$480,"skymaxmaroc.ma") -> 7 | E12: {=IFERROR(MEDIAN(IF('Niche Videos'!$B$2:$B$480="skymaxmaroc.ma",'Niche Videos'!$F$2:$F$480)),"n/a")} -> 1808 | F12: {=IFERROR(MAX(IF('Niche Videos'!$B$2:$B$480="skymaxmaroc.ma",'Niche Videos'!$F$2:$F$480)),"n/a")} -> 23700 | G12: Near-identical captions on 7 videos; repetition without variety does not scale.
A13: @markglassoffciel | B13: =IFERROR(INDEX('Niche Videos'!$C$2:$C$480,MATCH("markglassoffciel",'Niche Videos'!$B$2:$B$480,0)),"n/a") -> 12800 | C13: Tier 2: glass and aluminium | D13: =COUNTIF('Niche Videos'!$B$2:$B$480,"markglassoffciel") -> 16 | E13: {=IFERROR(MEDIAN(IF('Niche Videos'!$B$2:$B$480="markglassoffciel",'Niche Videos'!$F$2:$F$480)),"n/a")} -> 2134 | F13: {=IFERROR(MAX(IF('Niche Videos'!$B$2:$B$480="markglassoffciel",'Niche Videos'!$F$2:$F$480)),"n/a")} -> 52300 | G13: Same sales caption on its top videos.
A14: @pukapergola | B14: =IFERROR(INDEX('Niche Videos'!$C$2:$C$480,MATCH("pukapergola",'Niche Videos'!$B$2:$B$480,0)),"n/a") -> 18600 | C14: Tier 2: pergolas | D14: =COUNTIF('Niche Videos'!$B$2:$B$480,"pukapergola") -> 2 | E14: {=IFERROR(MEDIAN(IF('Niche Videos'!$B$2:$B$480="pukapergola",'Niche Videos'!$F$2:$F$480)),"n/a")} -> 10750 | F14: {=IFERROR(MAX(IF('Niche Videos'!$B$2:$B$480="pukapergola",'Niche Videos'!$F$2:$F$480)),"n/a")} -> 10900 | G14: 80-second videos pitching European-standard profiles, the same angle as your STRUGAL pitch.
A15: @rofof.fes | B15: =IFERROR(INDEX('Niche Videos'!$C$2:$C$480,MATCH("rofof.fes",'Niche Videos'!$B$2:$B$480,0)),"n/a") -> 328 | C15: Tier 3: local (Fès) | D15: =COUNTIF('Niche Videos'!$B$2:$B$480,"rofof.fes") -> 1 | E15: {=IFERROR(MEDIAN(IF('Niche Videos'!$B$2:$B$480="rofof.fes",'Niche Videos'!$F$2:$F$480)),"n/a")} -> 17300 | F15: {=IFERROR(MAX(IF('Niche Videos'!$B$2:$B$480="rofof.fes",'Niche Videos'!$F$2:$F$480)),"n/a")} -> 17300 | G15: 328 followers; a 10 s Arabic+French kitchen clip reached 17.3K.
A16: @rais48alum | B16: =IFERROR(INDEX('Niche Videos'!$C$2:$C$480,MATCH("rais48alum",'Niche Videos'!$B$2:$B$480,0)),"n/a") -> 2768 | C16: Tier 3: local (Oujda) | D16: =COUNTIF('Niche Videos'!$B$2:$B$480,"rais48alum") -> 3 | E16: {=IFERROR(MEDIAN(IF('Niche Videos'!$B$2:$B$480="rais48alum",'Niche Videos'!$F$2:$F$480)),"n/a")} -> 4874 | F16: {=IFERROR(MAX(IF('Niche Videos'!$B$2:$B$480="rais48alum",'Niche Videos'!$F$2:$F$480)),"n/a")} -> 5213
A17: @aluminiumziyou | B17: =IFERROR(INDEX('Niche Videos'!$C$2:$C$480,MATCH("aluminiumziyou",'Niche Videos'!$B$2:$B$480,0)),"n/a") -> 139 | C17: Tier 3: local (Fès) | D17: =COUNTIF('Niche Videos'!$B$2:$B$480,"aluminiumziyou") -> 1 | E17: {=IFERROR(MEDIAN(IF('Niche Videos'!$B$2:$B$480="aluminiumziyou",'Niche Videos'!$F$2:$F$480)),"n/a")} -> 3125 | F17: {=IFERROR(MAX(IF('Niche Videos'!$B$2:$B$480="aluminiumziyou",'Niche Videos'!$F$2:$F$480)),"n/a")} -> 3125 | G17: 139 followers.
A18: @chinawindowsdoors | B18: =IFERROR(INDEX('Niche Videos'!$C$2:$C$480,MATCH("chinawindowsdoors",'Niche Videos'!$B$2:$B$480,0)),"n/a") -> 206000 | C18: International | D18: =COUNTIF('Niche Videos'!$B$2:$B$480,"chinawindowsdoors") -> 5 | E18: {=IFERROR(MEDIAN(IF('Niche Videos'!$B$2:$B$480="chinawindowsdoors",'Niche Videos'!$F$2:$F$480)),"n/a")} -> 2000000 | F18: {=IFERROR(MAX(IF('Niche Videos'!$B$2:$B$480="chinawindowsdoors",'Niche Videos'!$F$2:$F$480)),"n/a")} -> 9000000 | G18: One mechanism, shot clean, under 20 s, English text overlay.
A19: @windowhome1 | B19: =IFERROR(INDEX('Niche Videos'!$C$2:$C$480,MATCH("windowhome1",'Niche Videos'!$B$2:$B$480,0)),"n/a") -> 208900 | C19: International | D19: =COUNTIF('Niche Videos'!$B$2:$B$480,"windowhome1") -> 2 | E19: {=IFERROR(MEDIAN(IF('Niche Videos'!$B$2:$B$480="windowhome1",'Niche Videos'!$F$2:$F$480)),"n/a")} -> 3000000 | F19: {=IFERROR(MAX(IF('Niche Videos'!$B$2:$B$480="windowhome1",'Niche Videos'!$F$2:$F$480)),"n/a")} -> 3000000 | G19: Sliding door with no floor track (3.0M twice).
A20: @omy.window.and.door0 | B20: =IFERROR(INDEX('Niche Videos'!$C$2:$C$480,MATCH("omy.window.and.door0",'Niche Videos'!$B$2:$B$480,0)),"n/a") -> 16400 | C20: International | D20: =COUNTIF('Niche Videos'!$B$2:$B$480,"omy.window.and.door0") -> 1 | E20: {=IFERROR(MEDIAN(IF('Niche Videos'!$B$2:$B$480="omy.window.and.door0",'Niche Videos'!$F$2:$F$480)),"n/a")} -> 3200000 | F20: {=IFERROR(MAX(IF('Niche Videos'!$B$2:$B$480="omy.window.and.door0",'Niche Videos'!$F$2:$F$480)),"n/a")} -> 3200000
A21: @siddiquealuminumandglass | B21: =IFERROR(INDEX('Niche Videos'!$C$2:$C$480,MATCH("siddiquealuminumandglass",'Niche Videos'!$B$2:$B$480,0)),"n/a") -> 12100 | C21: International | D21: =COUNTIF('Niche Videos'!$B$2:$B$480,"siddiquealuminumandglass") -> 4 | E21: {=IFERROR(MEDIAN(IF('Niche Videos'!$B$2:$B$480="siddiquealuminumandglass",'Niche Videos'!$F$2:$F$480)),"n/a")} -> 147450 | F21: {=IFERROR(MAX(IF('Niche Videos'!$B$2:$B$480="siddiquealuminumandglass",'Niche Videos'!$F$2:$F$480)),"n/a")} -> 1800000 | G21: Telescopic sliding door, 1.8M with 12K followers.
A23: Full competitor map (from the report)
A24: Tier 1: kitchen fabricators with huge reach (not your peers, but their format is a template)
A25: • @proalumad: 602K followers, median 1.3M views on the 7 videos I saw. Short silent reveals, Arabic hashtags, no spoken caption.
A26: • @alu.mamoune (18K), @alocuisines (47K), @aluminium_oujaiou (24K), @zaki.aluminiumpro (13K, median 18K, best 162K).
A27: • @aluminooo (75K): shower cabins with a WhatsApp number.
A28: Tier 2: suppliers, the closest to what you do
A29: Account | B29: Followers | C29: What they post | G29: Read
A30: @rm_accessoires1 | B30: 2.3K | C30: Wholesale hardware ("Charnière 3D… للبيع بالجملة"), 16s clip | G30: 8.3K views for a tiny account. Wholesale hardware demos do get seen.
A31: @skymaxmaroc.ma | B31: 3.2K | C31: WPC cladding supplier, near-identical captions on 7 videos | G31: Median 1.8K; the best one hit 23.7K. Repetition without variety doesn't scale.
A32: @markglassoffciel | B32: 12.8K | C32: Glass and aluminium; the same sales caption on its top videos | G32: Median 2.1K; a few reach ~50K
A33: @pukapergola | B33: 18.6K | C33: Bioclimatic pergolas, 80s videos pitching "profils certifiés normes européennes" | G33: ~10.7K each. Same "European standards" angle as your STRUGAL pitch.
A35: Tier 3: your actual local competitors (Fès / Meknès / Oujda)
A36: Almost empty. Only 14 of 479 videos mention Fès, Meknès, Taza, Oujda, Nador or nearby, and a few of those aren't aluminium at all. The notable ones: @rofof.fes (328 followers, a 10s Arabic+French kitchen clip at 17.3K), @rais48alum (Oujda, 2.8K followers, 2.7K–5.2K per video), @aluminiumziyou (139 followers). Nobody is the "profile supplier of the Fès region" on TikTok.
A37: International (borrow the visuals, not the language)
A38: • @chinawindowsdoors, @windowhome1, @omy.window.and.door0, @siddiquealuminumandglass all follow one formula: one mechanism, shot clean, under 20s, English text overlay. They hold the views record in the niche.
A39: The gaps nobody fills (in my sample)
A40: 1. Nobody pairs "official distributor" authority with real stock footage, a trust angle you already own.
A41: 2. Nobody shows technical know-how as entertainment (your dust-fix video proves the appetite).
A42: 3. Nobody has the AR/3D tool, or at least nobody is showing one.
A43: 4. Fès/Sefrou is open.
...

Sheet 20 Ideas
A1: # | B1: Pillar | C1: Idea | D1: Title in the first ideas list | E1: Hook (FR / Darija) | F1: Shots (summary) | G1: Length | H1: Triggers | I1: Evidence basis | J1: Why | K1: Caption & tags | L1: CTA / safety | M1: Shoot session
A2: 1 | B2: Stock, trucks, colours | C2: "Ce camion part pour [ville]" | E2: Ce camion part pour Meknès ce matin / هاد الكاميو غادي لمكناس دابا | F2: (1) truck loaded with bars at the store, (2) it pulls away, (3) city name appears on screen. No talking. 10–16s. | G2: 12–15s | H2: Rewatch · Local · Real | I2: Yours (your best video, 14.7K views, 127 likes, 20 shares) | J2: Yours: the truck video is your best at 14.7K views. Make it a weekly series and change the city each time, so you reach local audiences and show "livraison partout au Maroc" without saying it. | K2: Livraison du jour 🚚 #aluminium #maroc #fes #meknes #نجارة_الألمنيوم | M2: Stock & trucks
A3: 2 | B3: Stock, trucks, colours | C3: "Même profil, 6 teintes" | E3: Même profil. 6 teintes. Laquelle choisit ton client ? / نفس البروفيل، 6 ألوان. أي لون غادي يختار الزبون؟ | F3: (1) walk down the aisle, (2) each colour labelled as it passes: noir, gris naturel, fauxbois, blanc 9010, gris platine, gris givré, (3) end on the same section in three colours side by side. 15–22s. | G3: 18–21s | H3: Comment · Rewatch · Real | I3: Yours (stock walk, 8K views) | J3: Yours: the stock walk got 8K. The side-by-side ending turns a passive tour into a choice people comment on. | K3: Quelle teinte pour ta menuiserie ? 👇 #aluminium #fes #maroc #menuiserie #strugal | M3: Stock & trucks
A4: 3 | B4: Stock, trucks, colours | C4: "Arrivage" | E4: Nouvel arrivage S88RP / وصلات السلعة الجديدة | F4: a delivery being unloaded or a fresh bundle opened. Natural sound only. 8–12s. | G4: 8–12s | H4: Rewatch · Real | I4: Yours/Niche (raw stock is what your audience watches; very short silent clips are @proalumad's format) | J4: Yours/Niche: raw stock footage is what your audience already watches. Very short silent clips are what the biggest Moroccan account (@proalumad) uses. | K4: Arrivage ✅ #aluminium #strugal #fes #maroc #نجارة_الألمنيوم | M4: Stock & trucks
A5: 4 | B5: Stock, trucks, colours | C5: Folding mosquito net in three colours | E5: Moustiquaire plissée : gris givré, blanc, quartz / الناموسية المطوية فـ 3 ألوان | F5: hands pull the net across a window, one colour after another. 10–15s. | G5: 12–15s | H5: Share · Real | I5: Yours (25 shares on 2.7K views, a high ratio) | J5: Yours: your May mosquito-net video had 25 shares on 2.7K views, which is a high share count for its reach, so people send it to someone who needs one. | K5: Moustiquaire plissée : 3 teintes disponibles #moustiquaire #fenetre #maroc #fes #aluminium | M5: Stock & trucks
A6: 5 | B6: Counter tips (your most-saved format) | C6: "L'astuce du comptoir" (series) | D6: "Une astuce de 20 secondes" (dust fix, part 2) | E6: Une astuce de 20 secondes qui évite les retours / حيلة د 20 ثانية كتحميك من المشاكل | F6: same counter, same camera as your Sept video. Hold the profile and part, show one fix, finish with a question: Et toi, tu fais comment ? 20–30s. | G6: 22–28s | H6: Save · Share · Comment | I6: Yours (the dust-fix video has your most saves 23, shares 26, comments 11) | J6: Yours: the dust-fix video has the most saves (23), shares (26) and comments (11) of anything you've posted. The fixed setup lets viewers recognise the series. Run it weekly and pick topics from real customer questions. | K6: a question. Tu fais comment, toi ? 👇 #aluminium #menuiserie #fes #maroc #نجارة_الألمنيوم | M6: Counter
A7: 6 | B7: Counter tips (your most-saved format) | C7: S70P vs S90RP in your hands | E7: Où est la rupture de pont thermique ? / فين كاينة قطعة العزل الحراري؟ | F7: two profiles side by side, finger on the thermal barrier, then the frame sizes (your site: S90 has a 90 mm frame). 20–30s. | G7: 22–25s | H7: Save · Comment · Rewatch | I7: Untested (your site describes exactly this demo) | J7: Yours/Untested: your site says handling profiles "apprend en deux minutes ce qu'un catalogue met une heure à expliquer". This is that, on camera. | K7: S70P ou S90RP ? 👇 #coulissant #aluminium #menuiserie #fes #maroc | M7: Counter
A8: 7 | B8: Counter tips (your most-saved format) | C8: Quiz: "Quel profil porte 400 kg ?" | E8: Lequel porte 400 kg par vantail ? / شمن بروفيل كيحمل 400 كيلو؟ | F8: four profile close-ups labelled S70P, S90RP, S88RP, S110P. Pause 2 seconds, reveal S110P. Pin the full list in a comment: S70P 80 kg, S90RP 160 kg, S88RP 200–300 kg, S110P 400 kg (from your site). | G8: 15s | H8: Comment · Rewatch | I8: Untested | J8: Untested: built-in comment bait with a checkable answer. Don't include the S125RP in the options, because your site flags its limits as needing validation. | K8: Ton avis ? 👇 #aluminium #coulissant #menuiserie #maroc #fes | M8: Counter
A9: 8 | B9: Counter tips (your most-saved format) | C9: "Pourquoi deux devis sont différents" | D9: "Pourquoi deux devis de profilés sont différents" | E9: Même profilé, deux prix. Pourquoi ? / علاش جوج devis د البروفيلي مختلفين فالثمن؟ | F9: four quick text beats, one per factor from your FAQ: référence, quantité, finition, destination. Film the presenter at the counter. 20s. | G9: 20s | H9: Save · Share | I9: Niche (price/devis captions: median 12K views, save rate 0.38%, n=30) | J9: Niche: captions about price/devis had a median of 12K views and a high save rate (0.38%, n=30). It needs no actual prices. | K9: Les 4 choses qui changent le prix #aluminium #devis #menuiserie #fes #maroc | M9: Counter
A10: 9 | B10: The 3D/AR tool | C10: "Il hésite ? Montre-lui chez lui" | E10: Ton client n'arrive pas à se projeter ? / الزبون ما قادرش يتخيل؟ شوف هاد الحل | F10: screen recording. Empty terrace, then a pergola appears at real size, rotates, changes colour. 15–25s. | G10: 20–25s | H10: Share · Rewatch · Comment | I10: Untested (nobody in the sample shows this) | J10: Untested, but it's the one thing no competitor in my sample shows, and your site gives the selling points (no app, loads in about a second on 4G). | K10: Voir sa pergola chez soi avant de signer 🤯 #pergola #pergolabioclimatique #maroc #fes #بيرغولا | L10: CTA: Menuisiers : demandez votre lien. It's for professional customers only, which makes it exclusive. | M10: Screen recording
A11: 10 | B11: The 3D/AR tool | C11: "Pergola configurée en 30 secondes" | D11: Pergola in 30 seconds | E11: Une pergola 4,20 × 6,00 m configurée en 30 secondes / بيرغولا فـ 30 ثانية | F11: screen recording with a visible timer: size, colour, blades, LED, then the WhatsApp quote request arriving. 30s. | G11: 30s | H11: Rewatch · Share | I11: Untested | J11: Untested: speed-run formats work as proof. The WhatsApp ending shows the benefit for the menuisier: a complete request with sizes and finish. | K11: Un devis complet en 30 secondes #pergola #aluminium #devis #maroc #fes | M11: Screen recording
A12: 11 | B12: The 3D/AR tool | C12: A menuisier and his client | E12: Comment ce menuisier convainc son client avant la signature / كيفاش هاد النجار كيقنع الزبون قبل ما يوقع | F12: ask a customer workshop to film themselves showing the tool to a client (their own logo and link). Tag them. 20–30s. | G12: 20–30s | H12: Share · Real | I12: Untested | J12: Untested: a customer's own video is more credible than yours, and they'll repost it. Start with 3 workshops. | K12: Montrer avant de vendre #menuisier #aluminium #maroc #fes #pergola | M12: Ask a favour (3 customer workshops)
A13: 12 | B13: "One clever mechanism" | C13: The window that disappears | E13: La fenêtre qui disparaît / الشباك لي كيتخبى فالحيط | F13: an S88RP with galandage: the leaf slides fully into the wall. No talking. 8–12s. | G13: 10–12s | H13: Rewatch · Share | I13: Niche (one surprising mechanism, under 20 seconds: 1.8M to 9M views for others) | J13: Niche: the biggest videos here show a single surprising mechanism in under 20 seconds (1.8M to 9M views). Your site lists galandage as an S88RP option. | K13: La fenêtre qui disparaît 👀 #fenetre #coulissant #galandage #maroc #نجارة_الألمنيوم | M13: Stock & trucks
A14: 13 | B14: "One clever mechanism" | C14: The thinnest frame (S86RP) | D14: The thinnest frame in the range | E14: 42 mm au centre. Le plus fin. / أنحف بروفيل | F14: close-up of the S86RP centre section against a bright view. 8–10s. | G14: 8–12s | H14: Rewatch · Share | I14: Niche (same format as #12), built on your own spec | J14: Niche: same format as #12, based on your own spec (42 mm at the centre). | K14: Le plus fin du catalogue #coulissant #aluminium #architecture #maroc #fes | M14: Stock & trucks
A15: 14 | B15: "One clever mechanism" | C15: "400 kg sur un seul vantail" | D15: "400 kg… pour de vrai ?" | E15: Un vantail de 400 kg ? / واش بصح كيحمل 400 كيلو؟ | F15: loads added in steps on a supervised mock-up, with a clean cut at the end. 15–20s. | G15: 17s | H15: Rewatch · Comment | I15: Untested | J15: Untested: spectacle plus a spec people remember. | K15: Un vantail de 400 kg 🤯 #coulissant #aluminium #maroc #fes #architecture | L15: Safety: use a rig, not real glass, and don't imply it's a certified test. The figure comes from your site, so check it against the STRUGAL sheet first. | M15: Try later (needs safe rig)
A16: 15 | B16: Kitchens and dressings | C16: Integrated handle, silent reveal | E16: La poignée qu'on ne voit pas / المقبض لي ما كيبانش | F16: a kitchen door opens by its integrated handle profile. No talking, no voiceover. 5–10s. | G16: 7s | H16: Rewatch · Share | I16: Niche (kitchen captions: median ~30K views; @proalumad's 7-second silent reveal hit 8.3M) | J16: Niche: kitchens have a median of ~30K views in this sample, and @proalumad's 7-second silent kitchen reveal reached 8.3M. Kitchen fabricators are your customers, so the people who watch are the people who buy. | K16: المقبض لي ما كيبانش #cuisinealuminium #مطابخ_حديثة_المنيوم #fes #maroc | M16: Kitchen / dressing
A17: 16 | B17: Kitchens and dressings | C17: One dressing, three finishes | E17: Bicolore, effet bois ou anodisé ? / أي تشطيب كتفضل؟ | F17: the same profile in three finishes, wipe or swipe between them. 10–15s. | G17: 13s | H17: Comment · Rewatch | I17: Niche/Untested | J17: Niche/Untested: your site names these finishes for the S90RP, and a "pick one" question drives comments. | K17: Ton choix ? #dressing #aluminium #maroc #fes #design | M17: Kitchen / dressing
A18: 17 | B18: Humour, trust and replies | C18: Skit: "un petit coulissant" | E18: Le client veut un « petit coulissant »… / بغيت غير coulissant صغير… | F18: the client holds out his hands, then a tape measure reads 4 metres. 15s, Darija, two people. | G18: 15s, Darija, French subtitles | H18: Share · Comment | I18: Untested. Try 2–3 skits and keep it only if it earns shares. | J18: Untested: relatable humour about the menuisier's daily life. Try it 2 or 3 times, then keep it only if it earns shares. | K18: Tous les menuisiers connaissent 😅 #menuisier #aluminium #maroc #humour #fes | M18: Try later
A19: 18 | B19: Humour, trust and replies | C19: "L'aluminium rouille ?" | E19: L'aluminium rouille ? / واش الألمنيوم كيصدا؟ | F19: answer in one sentence, then show why (your exterior page: it forms a thin protective oxide layer and doesn't rust). 15–20s. | G19: 15–20s | H19: Share · Save | I19: Untested (your exterior page already has the facts) | J19: Untested: your site already has the explanation. Myth-busting is easy to share with a customer who asked the same thing. | K19: Le mythe qui revient tout le temps #aluminium #menuiserie #maroc #fes #bricolage | M19: Try later
A20: 19 | B20: Humour, trust and replies | C20: "Touchez avant de commander" (Sefrou showroom) | E20: Le showroom où tu peux tout comparer en main / جرّب بيدك قبل ما تطلب | F20: walk through the Sefrou showroom, pick up two profiles, show opening hours (lundi–samedi, 9h–19h). 20–25s. | G20: 20–22s | H20: Local · Real | I20: Yours/Untested (your best videos are shop-floor footage) | J20: Yours/Untested: your top videos are shop-floor footage. This turns the showroom into the reason to visit. | K20: Le showroom STRUGAL de Sefrou #sefrou #strugal #aluminium #maroc #fes | M20: Counter
A21: 20 | B21: Humour, trust and replies | C21: Reply video to a menuisier's comment | D21: Reply to a menuisier's comment | E21: the commenter's question on screen as a video reply, then your answer. | F21: 15–30s at the counter, one question, one answer. | G21: 15–30s | H21: Comment · Local | I21: Niche (your comment counts are only 1–11) | J21: Niche: your comment counts are 1–11, so any reply you give is also a reason for them to comment again. These cost almost nothing to film. | K21: Réponse à @… #aluminium #menuiserie #fes #maroc | M21: Counter
A23: How to read the ideas (from the ideas file)
B24: Built from the research in prompolu-content-strategy.md: your 10 TikToks, 479 niche videos (188 Moroccan) and the specs on prompolu.com.
B25: How to read each card
B26: • Hook: the on-screen text for the first 1–2 seconds, in French and Darija. The Darija lines are drafts, so change them to how you actually speak.
B27: • Shots: what to film, beat by beat.
B28: • Why: the evidence. Yours = your own TikTok results. Niche = the 479-video sample. Untested = a reasonable bet with no data behind it.
B29: • Length is a target, not a rule. Everything is 9:16.

Sheet Briefs
A1: # | B1: Idea | C1: Pillar | D1: Length | E1: Triggers | F1: Evidence | G1: Why it can travel | H1: Setup | I1: Hooks (A/B/bank) | J1: Sound & edit | K1: Caption | L1: Tags | M1: Pinned comment | N1: Next episodes | O1: Watch-outs | P1: Win signal | Q1: Extra notes
A2: 1 | B2: "Ce camion part pour [ville]" | C2: Stock, trucks, colours | D2: 12–15s | E2: Rewatch · Local · Real | F2: Yours (your best video, 14.7K views, 127 likes, 20 shares) | G2: spectacle (a truck piled high with bars) plus a local reveal. It shows "livraison partout au Maroc" without saying it. | H2: Setup: film from behind at street level. Fix the phone (wall, tripod or a helper standing still). Morning light. Ask someone to tighten the straps on camera. Check: nothing in frame that identifies a customer. | I2: Hook A (statement): Ce camion part pour Meknès ce matin / هاد الكاميو غادي لمكناس دابا Hook B (curiosity): Devine où part ce camion 🚚, with the city hidden until 10s. People watch to the end and comment guesses. | J2: no cuts during the drive-away; it's more satisfying as one take. Use a different city each time. | K2: Livraison du jour 🚚 | L2: #aluminium #maroc #fes #meknes #نجارة_الألمنيوم | M2: On livre partout au Maroc. Dites-nous votre ville 👇 (the city comments are proof, and your next videos' destinations). | N2: (a) the truck arriving at the workshop, with the menuisier's permission; (b) loading in time-lapse (8×); (c) after 10 deliveries, a map video with pins; (d) "Livré à Taza / Oujda / Casablanca" to open new regions. | O2: blur faces and plates that aren't yours. Don't block the road for the shot. | P2: beats 14.7K, or shares above 0.15% of views.
A3: 2 | B3: "Même profil, 6 teintes" | C3: Stock, trucks, colours | D3: 18–21s | E3: Comment · Rewatch · Real | F3: Yours (stock walk, 8K views) | G3: a quick sequence people replay to catch every colour, plus a pick-one question. | H3: walk the aisle at a steady pace, phone at chest height in both hands (or a gimbal). Bright, even light. | I3: Hook A: Même profil. 6 teintes. / نفس البروفيل، 6 ألوان Hook B (Arabic first): أي لون كتختار لفيلا فاس؟ | J3: time each label to a footstep. Add "Teintes indicatives (écran)" in small text, which your own site says about screen colours. | K3: Quelle teinte pour ta menuiserie ? 👇 | L3: #aluminium #fes #maroc #menuiserie #strugal | M3: the colour list and Demandez le stock du jour sur WhatsApp. | N3: "Teinte du mois"; RAL 7016 vs 9016 on a real window (your site's AR examples use RAL 7016, 9006 and 9016); the same window in 3 colours. | O3: only list colours actually in stock. | P3: comment replies naming a number or colour, and shares above 0.2%.
A4: 3 | B4: "Arrivage" | C4: Stock, trucks, colours | D4: 8–12s | E4: Rewatch · Real | F4: Yours/Niche (raw stock is what your audience watches; very short silent clips are @proalumad's format) | G4: it's satisfying. The sound of straps and sliding bars is half of it. | H4: film only a real delivery. Hold the phone close to the strap and the bundle. Wind off, no music. | I4: Nouvel arrivage S88RP / وصلات السلعة الجديدة | K4: Arrivage ✅ | L4: #aluminium #strugal #fes #maroc #نجارة_الألمنيوم | M4: Quelle référence vous cherchez ? | N4: "Arrivage #2"; empty truck → full shelf in 15s; the oldest and newest profile in the store. | O4: announce only what's really in stock, or WhatsApp fills with disappointed messages. | P4: WhatsApp enquiries naming the reference.
A5: 4 | B5: Folding mosquito net in three colours | C5: Stock, trucks, colours | D5: 12–15s | E5: Share · Real | F5: Yours (25 shares on 2.7K views, a high ratio) | G5: people send it to someone who needs one. | H5: a real window in daylight; three net samples. | I5: Hook A: Elle se plie dans le coin 👀 / الناموسية كتتطوى فالركن Hook B: Fenêtre ouverte, moustiques dehors. | K5: Moustiquaire plissée : 3 teintes disponibles | L5: #moustiquaire #fenetre #maroc #fes #aluminium | M5: Tag quelqu'un qui en a besoin 👇 (this prompts the shares you already get). | N5: net on a French door; the 3 colours on 3 window colours; how it's fitted (only if you can show it simply). | O5: strongest from spring to summer. Re-post it in April. | P5: shares per 1,000 views above 5.
A6: 5 | B6: "L'astuce du comptoir" (series) | C6: Counter tips (your most-saved format) | D6: 22–28s | E6: Save · Share · Comment | F6: Yours (the dust-fix video has your most saves 23, shares 26, comments 11) | G6: it's useful to exactly the person you want to reach, and menuisiers send tricks to each other. | H6: the same counter, camera and outfit as the September video so viewers recognise it. A small tripod at eye level, warm light, a clean background. The series name is a small text tag in the corner, not a separate intro. | I6: Hook bank: Une erreur qui coûte un retour de chantier / غلطة كتكلف رجوع من الورش · Personne ne t'a montré ça · Une astuce de 20 secondes / حيلة د 20 ثانية | K6: a question. Tu fais comment, toi ? 👇 | L6: #aluminium #menuiserie #fes #maroc #نجارة_الألمنيوم | M6: the tip in one line (saveable). | N6: reply videos to the best comments (#20); "Partie 2"; a "wrong way / right way" split screen. | O6: every technical claim must be correct. If you aren't sure, ask STRUGAL or your most experienced fitter. | P6: saves ≥ shares, and menuisiers posting their own tricks in the comments. | Q6: Topic backlog: (the first five come from your site, so they're safe; the rest are yours to validate): 1. Dust fix for the flat lock, part 2 (your own). 2. What the letters mean: P, R, RP (your site explains them). 3. Maximum glazing per system (S70P 21 mm, S88 32 mm). 4. Leaf weight vs system choice. 5. How to write a quote request (reference, quantity, finish, city). 6. Where the thermal barrier sits and why it matters. 7. Your own workshop tricks: rollers, drainage, gaskets, silicone. Tell me which you want expanded.
A7: 6 | B7: S70P vs S90RP in your hands | C7: Counter tips (your most-saved format) | D7: 22–25s | E7: Save · Comment · Rewatch | F7: Untested (your site describes exactly this demo) | G7: "find the thermal barrier" is a small game viewers try to win. | H7: two corner samples on the counter, a pen, a camera looking straight down. | I7: Où est la barrette ? / فين كاينة قطعة العزل؟ | K7: S70P ou S90RP ? 👇 | L7: #coulissant #aluminium #menuiserie #fes #maroc | M7: a mini comparison table. | N7: S88RP vs S90RP (your FAQ covers it); S70R vs S70P ("jusqu'à 20% d'économies d'énergie" per your site). | O7: Uw and acoustic values depend on the glazing and configuration, so write "selon fiche technique" on screen. | P7: comments answering "lequel", saves.
A8: 7 | B8: Quiz: "Quel profil porte 400 kg ?" | C8: Counter tips (your most-saved format) | D8: 15s | E8: Comment · Rewatch | F8: Untested | H8: four close-ups on one background; a big countdown graphic. | I8: Lequel porte 400 kg ? / شمن بروفيل كيحمل 400 كيلو؟ | J8: end on the answer, then cut straight back to the four tiles so it loops and people rewatch to check. | K8: Ton avis ? 👇 | L8: #aluminium #coulissant #menuiserie #maroc #fes | M8: the full table: S70P 80 kg · S90RP 160 kg · S88RP 200–300 kg · S110P 400 kg. | N8: "Quel système pour 3,3 × 3,2 m ?" (S88: max 3300 × 3200 mm); "Quel vitrage max ?" (21 / 26 / 32 mm). | O8: keep the S125RP out of the options, because its limits come with a validation note on your site. Add "Valeurs max, voir fiche technique". | P8: a lot of comments, wrong answers included. Reply to those.
A9: 8 | B9: "Pourquoi deux devis sont différents" | C9: Counter tips (your most-saved format) | D9: 20s | E9: Save · Share | F9: Niche (price/devis captions: median 12K views, save rate 0.38%, n=30) | G9: it removes a frustration every menuisier has with suppliers. And it needs no prices. | I9: علاش جوج devis د البروفيلي مختلفين فالثمن؟ | K9: Les 4 choses qui changent le prix | L9: #aluminium #devis #menuiserie #fes #maroc | M9: Pinned comment (the save): a copy-paste WhatsApp template: Référence : … / Quantité (barres ou ml) : … / Finition : … / Ville : … | N9: "Barres ou mètres ?"; "Comment lire une référence STRUGAL"; "Compte pro : quand c'est utile". | O9: no prices unless you decide to publish them. | P9: saves above shares, and WhatsApp messages that follow your template.
